**转载**

> [C++异常处理](https://www.runoob.com/cplusplus/cpp-exceptions-handling.html)

# 异常

C++ 中的异常处理涉及 3 个关键字：`try`, `catch`, `throw`。

- throw 负责抛出异常
- catch 负责捕获异常
- try 块中的代码标识将被激活的特定异常。

```c++
#include <iostream>
using namespace std;

double division(int a, int b) {
    if (b == 0) {
        throw "division by zero";
    }
    return a/b;
}

int main() {
    int x = 10, y = 0;
    try {
        division(x, y);
    } catch (const char* msg) {
        cerr << msg << endl;
    }
    return 0;
}
// output
division by zero
```

​		上面的代码中抛出了一个类型为 const char* 的异常，因此当捕获该异常时，必须在 catch 块中使用 `const char*`。

## C++ 标准的异常

​		C++ 提供了一系列标准的异常，定义在 `<exception>` 中，它们以继承层次结构被组织起来。

![C++ 异常的层次结构](异常.assets/exceptions_in_cpp.png)

**异常说明**

| 异常                   | 描述                                                         |
| :--------------------- | :----------------------------------------------------------- |
| **std::exception**     | 该异常是所有标准 C++ 异常的父类。                            |
| std::bad_alloc         | 该异常可以通过 **new** 抛出。                                |
| std::bad_cast          | 该异常可以通过 **dynamic_cast** 抛出。                       |
| std::bad_exception     | 这在处理 C++ 程序中无法预期的异常时非常有用。                |
| std::bad_typeid        | 该异常可以通过 **typeid** 抛出。                             |
| **std::logic_error**   | 理论上可以通过读取代码来检测到的异常。                       |
| std::domain_error      | 当使用了一个无效的数学域时，会抛出该异常。                   |
| std::invalid_argument  | 当使用了无效的参数时，会抛出该异常。                         |
| std::length_error      | 当创建了太长的 std::string 时，会抛出该异常。                |
| std::out_of_range      | 该异常可以通过方法抛出，例如 std::vector 和 std::bitset<>::operator[]()。 |
| **std::runtime_error** | 理论上不可以通过读取代码来检测到的异常。                     |
| std::overflow_error    | 当发生数学上溢时，会抛出该异常。                             |
| std::range_error       | 当尝试存储超出范围的值时，会抛出该异常。                     |
| std::underflow_error   | 当发生数学下溢时，会抛出该异常。                             |

​		可以通过继承 exception 类来定义新的异常。

```c++
#include <exception>
#include <iostream>
using namespace std;

class my_exception: public exception {
public:
    const char* what() const throw () {
        return "my exception";
    }
};

int main() {
    try {
        throw my_exception();
    } catch(my_exception& e) {
        cout << e.what() << endl;
    } catch(exception& e) {
        // 其他异常
        cout << e.what() << endl;
    }
    return 0;
}
// output
my exception
```

